Workbook

Sheet Cover & Instructions
B2: HOTEL FINANCIAL REPORTING TEMPLATES
B3: Uniform System of Accounts for the Lodging Industry (USALI) — 11th Revised Edition
B5: A complete, ready-to-use set of operating statements and departmental schedules formatted in conformity with the USALI standard adopted across the global hotel industry.
B8: How to use this workbook
B9: 1. Open "Setup & Assumptions" and enter your property name, period and currency.
B10: 2. Enter actual / budget / prior-year figures into the blue cells on each departmental schedule.
B11: 3. Departmental totals roll up automatically to the two Summary Operating Statements.
B12: 4. Review the "Operating Metrics & Ratios" sheet for auto-calculated KPIs (Occupancy, ADR, RevPAR, GOP, EBITDA).
B14: Colour legend
B15: Blue text | C15: Input cells — enter your figures here
B16: Black text | C16: Calculated totals and sub-totals — do not overwrite
B17: Green text | C17: Links pulling values from another worksheet
B19: Schedules included
B20: Summary Operating Statement | C20: For Operators (EBITDA less Replacement Reserve) and For Owners (Net Income)
B21: Schedule 1 | C21: Rooms
B22: Schedule 2 | C22: Food and Beverage
B23: Schedule 3 + 3-1/3-2/3-3/3-x/3-xx | C23: Other Operated Departments (Golf, Health Club/Spa, Parking, Generic, Minor)
B24: Schedule 4 | C24: Miscellaneous Income
B25: Schedule 5 | C25: Administrative and General
B26: Schedule 6 | C26: Information and Telecommunications Systems
B27: Schedule 7 | C27: Sales and Marketing
B28: Schedule 8 | C28: Property Operation and Maintenance
B29: Schedule 9 | C29: Utilities
B30: Schedule 10 | C30: Management Fees
B31: Schedule 11 | C31: Non-Operating Income and Expenses
... B35: Operating Metrics & Ratios | C35: Occupancy, ADR, RevPAR, Total RevPAR, GOP, GOPPAR, EBITDA and more
B37: This template is provided for financial-reporting convenience. It reproduces the line-item structure of the USALI 11th Revised Edition for practitioner use; it is not the copyrighted text of the standard. The USALI is published by the Hospitality Financial and Technology Professionals (HFTP) and the American Hotel & Lodging Association. Refer to the official publication for full account definitions and guidance.

Sheet Setup & Assumptions
A1: SETUP & ASSUMPTIONS
A3: Property Details
A4: Property / Hotel Name | B4: Enter property name
A5: Reporting Period / Year | B5: e.g. January 2026 / FY2026
A6: Reporting Currency | B6: INR
A7: Prepared By
A8: Date Prepared
A10: Notes on Use
A11: • The Property Name and Reporting Period entered above flow automatically to the header of every schedule.
A12: • Enter all amounts in the blue (input) cells only. Black figures are calculated; do not overwrite them.
A13: • Green figures are links pulling totals from other worksheets within this workbook.
A14: • Enter "Less: Allowances" and credit/recovery lines as positive numbers — the formulas subtract them.
A15: • The Replacement Reserve (Operators statement) and Interest / Depreciation / Amortization / Income Taxes
A16: (Owners statement) are entered directly on the respective Summary Operating Statement.
A17: • House Laundry (Sch 12) and Staff Dining (Sch 13) are allocated to operating departments and are not
A18: shown separately on the Summary Operating Statement.
A19: • You may delete line items that do not apply to your property. Do not add or rename approved USALI line
A20: items; instead create a supporting sub-account/sub-schedule that rolls into the appropriate line.

Sheet Summary Op Stmt (Operators)
A1: SUMMARY OPERATING STATEMENT [For Operators]
A2: Property: | B2: ='Setup & Assumptions'!$B$4 -> Enter property name | H2: Period / Year: | J2: ='Setup & Assumptions'!$B$5 -> e.g. January 2026 / FY2026
A3: Bottom line: EBITDA Less Replacement Reserve. Revenue/expense % is of Total Operating Revenue; departmental expense % is of departmental revenue.
B4: Current Period | H4: Year-To-Date
B5: Actual | D5: Forecast / Budget | F5: Prior Year | H5: Actual | J5: Forecast / Budget | L5: Prior Year
A6: Line Item | B6: $ | C6: % | D6: $ | E6: % | F6: $ | G6: % | H6: $ | I6: % | J6: $ | K6: % | L6: $ | M6: %
A7: Operating Statistics
A8: Rooms Available
A9: Rooms Sold
A10: Occupancy % | B10: =IF(B8=0,"",B9/B8) | D10: =IF(D8=0,"",D9/D8) | F10: =IF(F8=0,"",F9/F8) | H10: =IF(H8=0,"",H9/H8) | J10: =IF(J8=0,"",J9/J8) | L10: =IF(L8=0,"",L9/L8)
A11: ADR (Average Daily Rate) | B11: =IF(B9=0,"",B16/B9) | D11: =IF(D9=0,"",D16/D9) | F11: =IF(F9=0,"",F16/F9) | H11: =IF(H9=0,"",H16/H9) | J11: =IF(J9=0,"",J16/J9) | L11: =IF(L9=0,"",L16/L9)
A12: Rooms RevPAR | B12: =IF(B8=0,"",B16/B8) | D12: =IF(D8=0,"",D16/D8) | F12: =IF(F8=0,"",F16/F8) | H12: =IF(H8=0,"",H16/H8) | J12: =IF(J8=0,"",J16/J8) | L12: =IF(L8=0,"",L16/L8)
A13: Total RevPAR | B13: =IF(B8=0,"",B20/B8) | D13: =IF(D8=0,"",D20/D8) | F13: =IF(F8=0,"",F20/F8) | H13: =IF(H8=0,"",H20/H8) | J13: =IF(J8=0,"",J20/J8) | L13: =IF(L8=0,"",L20/L8)
A15: Operating Revenue
A16: Rooms | B16: ='Schedule 1 - Rooms'!B25 -> 0 | C16: =IF(OR('Summary Op Stmt (Operators)'!$B$20=0,'Summary Op Stmt (Operators)'!$B$20=""),"",B16/'Summary Op Stmt (Operators)'!$B$20) | D16: ='Schedule 1 - Rooms'!D25 -> 0 | E16: =IF(OR('Summary Op Stmt (Operators)'!$D$20=0,'Summary Op Stmt (Operators)'!$D$20=""),"",D16/'Summary Op Stmt (Operators)'!$D$20) | F16: ='Schedule 1 - Rooms'!F25 -> 0 | G16: =IF(OR('Summary Op Stmt (Operators)'!$F$20=0,'Summary Op Stmt (Operators)'!$F$20=""),"",F16/'Summary Op Stmt (Operators)'!$F$20) | H16: ='Schedule 1 - Rooms'!H25 -> 0 | I16: =IF(OR('Summary Op Stmt (Operators)'!$H$20=0,'Summary Op Stmt (Operators)'!$H$20=""),"",H16/'Summary Op Stmt (Operators)'!$H$20) | J16: ='Schedule 1 - Rooms'!J25 -> 0 | K16: =IF(OR('Summary Op Stmt (Operators)'!$J$20=0,'Summary Op Stmt (Operators)'!$J$20=""),"",J16/'Summary Op Stmt (Operators)'!$J$20) | L16: ='Schedule 1 - Rooms'!L25 -> 0 | M16: =IF(OR('Summary Op Stmt (Operators)'!$L$20=0,'Summary Op Stmt (Operators)'!$L$20=""),"",L16/'Summary Op Stmt (Operators)'!$L$20)
A17: Food and Beverage | B17: ='Schedule 2 - Food & Beverage'!B32 -> 0 | C17: =IF(OR('Summary Op Stmt (Operators)'!$B$20=0,'Summary Op Stmt (Operators)'!$B$20=""),"",B17/'Summary Op Stmt (Operators)'!$B$20) | D17: ='Schedule 2 - Food & Beverage'!D32 -> 0 | E17: =IF(OR('Summary Op Stmt (Operators)'!$D$20=0,'Summary Op Stmt (Operators)'!$D$20=""),"",D17/'Summary Op Stmt (Operators)'!$D$20) | F17: ='Schedule 2 - Food & Beverage'!F32 -> 0 | G17: =IF(OR('Summary Op Stmt (Operators)'!$F$20=0,'Summary Op Stmt (Operators)'!$F$20=""),"",F17/'Summary Op Stmt (Operators)'!$F$20) | H17: ='Schedule 2 - Food & Beverage'!H32 -> 0 | I17: =IF(OR('Summary Op Stmt (Operators)'!$H$20=0,'Summary Op Stmt (Operators)'!$H$20=""),"",H17/'Summary Op Stmt (Operators)'!$H$20) | J17: ='Schedule 2 - Food & Beverage'!J32 -> 0 | K17: =IF(OR('Summary Op Stmt (Operators)'!$J$20=0,'Summary Op Stmt (Operators)'!$J$20=""),"",J17/'Summary Op Stmt (Operators)'!$J$20) | L17: ='Schedule 2 - Food & Beverage'!L32 -> 0 | M17: =IF(OR('Summary Op Stmt (Operators)'!$L$20=0,'Summary Op Stmt (Operators)'!$L$20=""),"",L17/'Summary Op Stmt (Operators)'!$L$20)
A18: Other Operated Departments | B18: ='Schedule 3 - Other Op Depts'!B13 -> 0 | C18: =IF(OR('Summary Op Stmt (Operators)'!$B$20=0,'Summary Op Stmt (Operators)'!$B$20=""),"",B18/'Summary Op Stmt (Operators)'!$B$20) | D18: ='Schedule 3 - Other Op Depts'!D13 -> 0 | E18: =IF(OR('Summary Op Stmt (Operators)'!$D$20=0,'Summary Op Stmt (Operators)'!$D$20=""),"",D18/'Summary Op Stmt (Operators)'!$D$20) | F18: ='Schedule 3 - Other Op Depts'!F13 -> 0 | G18: =IF(OR('Summary Op Stmt (Operators)'!$F$20=0,'Summary Op Stmt (Operators)'!$F$20=""),"",F18/'Summary Op Stmt (Operators)'!$F$20) | H18: ='Schedule 3 - Other Op Depts'!H13 -> 0 | I18: =IF(OR('Summary Op Stmt (Operators)'!$H$20=0,'Summary Op Stmt (Operators)'!$H$20=""),"",H18/'Summary Op Stmt (Operators)'!$H$20) | J18: ='Schedule 3 - Other Op Depts'!J13 -> 0 | K18: =IF(OR('Summary Op Stmt (Operators)'!$J$20=0,'Summary Op Stmt (Operators)'!$J$20=""),"",J18/'Summary Op Stmt (Operators)'!$J$20) | L18: ='Schedule 3 - Other Op Depts'!L13 -> 0 | M18: =IF(OR('Summary Op Stmt (Operators)'!$L$20=0,'Summary Op Stmt (Operators)'!$L$20=""),"",L18/'Summary Op Stmt (Operators)'!$L$20)
A19: Miscellaneous Income | B19: ='Schedule 4 - Misc Income'!B22 -> 0 | C19: =IF(OR('Summary Op Stmt (Operators)'!$B$20=0,'Summary Op Stmt (Operators)'!$B$20=""),"",B19/'Summary Op Stmt (Operators)'!$B$20) | D19: ='Schedule 4 - Misc Income'!D22 -> 0 | E19: =IF(OR('Summary Op Stmt (Operators)'!$D$20=0,'Summary Op Stmt (Operators)'!$D$20=""),"",D19/'Summary Op Stmt (Operators)'!$D$20) | F19: ='Schedule 4 - Misc Income'!F22 -> 0 | G19: =IF(OR('Summary Op Stmt (Operators)'!$F$20=0,'Summary Op Stmt (Operators)'!$F$20=""),"",F19/'Summary Op Stmt (Operators)'!$F$20) | H19: ='Schedule 4 - Misc Income'!H22 -> 0 | I19: =IF(OR('Summary Op Stmt (Operators)'!$H$20=0,'Summary Op Stmt (Operators)'!$H$20=""),"",H19/'Summary Op Stmt (Operators)'!$H$20) | J19: ='Schedule 4 - Misc Income'!J22 -> 0 | K19: =IF(OR('Summary Op Stmt (Operators)'!$J$20=0,'Summary Op Stmt (Operators)'!$J$20=""),"",J19/'Summary Op Stmt (Operators)'!$J$20) | L19: ='Schedule 4 - Misc Income'!L22 -> 0 | M19: =IF(OR('Summary Op Stmt (Operators)'!$L$20=0,'Summary Op Stmt (Operators)'!$L$20=""),"",L19/'Summary Op Stmt (Operators)'!$L$20)
A20: Total Operating Revenue | B20: =B16+B17+B18+B19 -> 0 | C20: =IF(OR('Summary Op Stmt (Operators)'!$B$20=0,'Summary Op Stmt (Operators)'!$B$20=""),"",B20/'Summary Op Stmt (Operators)'!$B$20) | D20: =D16+D17+D18+D19 -> 0 | E20: =IF(OR('Summary Op Stmt (Operators)'!$D$20=0,'Summary Op Stmt (Operators)'!$D$20=""),"",D20/'Summary Op Stmt (Operators)'!$D$20) | F20: =F16+F17+F18+F19 -> 0 | G20: =IF(OR('Summary Op Stmt (Operators)'!$F$20=0,'Summary Op Stmt (Operators)'!$F$20=""),"",F20/'Summary Op Stmt (Operators)'!$F$20) | H20: =H16+H17+H18+H19 -> 0 | I20: =IF(OR('Summary Op Stmt (Operators)'!$H$20=0,'Summary Op Stmt (Operators)'!$H$20=""),"",H20/'Summary Op Stmt (Operators)'!$H$20) | J20: =J16+J17+J18+J19 -> 0 | K20: =IF(OR('Summary Op Stmt (Operators)'!$J$20=0,'Summary Op Stmt (Operators)'!$J$20=""),"",J20/'Summary Op Stmt (Operators)'!$J$20) | L20: =L16+L17+L18+L19 -> 0 | M20: =IF(OR('Summary Op Stmt (Operators)'!$L$20=0,'Summary Op Stmt (Operators)'!$L$20=""),"",L20/'Summary Op Stmt (Operators)'!$L$20)
A21: Departmental Expenses
A22: Rooms | B22: ='Schedule 1 - Rooms'!B81 -> 0 | C22: =IF(OR(B16=0,B16=""),"",B22/B16) | D22: ='Schedule 1 - Rooms'!D81 -> 0 | E22: =IF(OR(D16=0,D16=""),"",D22/D16) | F22: ='Schedule 1 - Rooms'!F81 -> 0 | G22: =IF(OR(F16=0,F16=""),"",F22/F16) | H22: ='Schedule 1 - Rooms'!H81 -> 0 | I22: =IF(OR(H16=0,H16=""),"",H22/H16) | J22: ='Schedule 1 - Rooms'!J81 -> 0 | K22: =IF(OR(J16=0,J16=""),"",J22/J16) | L22: ='Schedule 1 - Rooms'!L81 -> 0 | M22: =IF(OR(L16=0,L16=""),"",L22/L16)
A23: Food and Beverage | B23: ='Schedule 2 - Food & Beverage'!B42+'Schedule 2 - Food & Beverage'!B105 -> 0 | C23: =IF(OR(B17=0,B17=""),"",B23/B17) | D23: ='Schedule 2 - Food & Beverage'!D42+'Schedule 2 - Food & Beverage'!D105 -> 0 | E23: =IF(OR(D17=0,D17=""),"",D23/D17) | F23: ='Schedule 2 - Food & Beverage'!F42+'Schedule 2 - Food & Beverage'!F105 -> 0 | G23: =IF(OR(F17=0,F17=""),"",F23/F17) | H23: ='Schedule 2 - Food & Beverage'!H42+'Schedule 2 - Food & Beverage'!H105 -> 0 | I23: =IF(OR(H17=0,H17=""),"",H23/H17) | J23: ='Schedule 2 - Food & Beverage'!J42+'Schedule 2 - Food & Beverage'!J105 -> 0 | K23: =IF(OR(J17=0,J17=""),"",J23/J17) | L23: ='Schedule 2 - Food & Beverage'!L42+'Schedule 2 - Food & Beverage'!L105 -> 0 | M23: =IF(OR(L17=0,L17=""),"",L23/L17)
A24: Other Operated Departments | B24: ='Schedule 3 - Other Op Depts'!B20 -> 0 | C24: =IF(OR(B18=0,B18=""),"",B24/B18) | D24: ='Schedule 3 - Other Op Depts'!D20 -> 0 | E24: =IF(OR(D18=0,D18=""),"",D24/D18) | F24: ='Schedule 3 - Other Op Depts'!F20 -> 0 | G24: =IF(OR(F18=0,F18=""),"",F24/F18) | H24: ='Schedule 3 - Other Op Depts'!H20 -> 0 | I24: =IF(OR(H18=0,H18=""),"",H24/H18) | J24: ='Schedule 3 - Other Op Depts'!J20 -> 0 | K24: =IF(OR(J18=0,J18=""),"",J24/J18) | L24: ='Schedule 3 - Other Op Depts'!L20 -> 0 | M24: =IF(OR(L18=0,L18=""),"",L24/L18)
A25: Total Departmental Expenses | B25: =B22+B23+B24 -> 0 | C25: =IF(OR('Summary Op Stmt (Operators)'!$B$20=0,'Summary Op Stmt (Operators)'!$B$20=""),"",B25/'Summary Op Stmt (Operators)'!$B$20) | D25: =D22+D23+D24 -> 0 | E25: =IF(OR('Summary Op Stmt (Operators)'!$D$20=0,'Summary Op Stmt (Operators)'!$D$20=""),"",D25/'Summary Op Stmt (Operators)'!$D$20) | F25: =F22+F23+F24 -> 0 | G25: =IF(OR('Summary Op Stmt (Operators)'!$F$20=0,'Summary Op Stmt (Operators)'!$F$20=""),"",F25/'Summary Op Stmt (Operators)'!$F$20) | H25: =H22+H23+H24 -> 0 | I25: =IF(OR('Summary Op Stmt (Operators)'!$H$20=0,'Summary Op Stmt (Operators)'!$H$20=""),"",H25/'Summary Op Stmt (Operators)'!$H$20) | J25: =J22+J23+J24 -> 0 | K25: =IF(OR('Summary Op Stmt (Operators)'!$J$20=0,'Summary Op Stmt (Operators)'!$J$20=""),"",J25/'Summary Op Stmt (Operators)'!$J$20) | L25: =L22+L23+L24 -> 0 | M25: =IF(OR('Summary Op Stmt (Operators)'!$L$20=0,'Summary Op Stmt (Operators)'!$L$20=""),"",L25/'Summary Op Stmt (Operators)'!$L$20)
A26: Total Departmental Profit | B26: =B20-B25 -> 0 | C26: =IF(OR('Summary Op Stmt (Operators)'!$B$20=0,'Summary Op Stmt (Operators)'!$B$20=""),"",B26/'Summary Op Stmt (Operators)'!$B$20) | D26: =D20-D25 -> 0 | E26: =IF(OR('Summary Op Stmt (Operators)'!$D$20=0,'Summary Op Stmt (Operators)'!$D$20=""),"",D26/'Summary Op Stmt (Operators)'!$D$20) | F26: =F20-F25 -> 0 | G26: =IF(OR('Summary Op Stmt (Operators)'!$F$20=0,'Summary Op Stmt (Operators)'!$F$20=""),"",F26/'Summary Op Stmt (Operators)'!$F$20) | H26: =H20-H25 -> 0 | I26: =IF(OR('Summary Op Stmt (Operators)'!$H$20=0,'Summary Op Stmt (Operators)'!$H$20=""),"",H26/'Summary Op Stmt (Operators)'!$H$20) | J26: =J20-J25 -> 0 | K26: =IF(OR('Summary Op Stmt (Operators)'!$J$20=0,'Summary Op Stmt (Operators)'!$J$20=""),"",J26/'Summary Op Stmt (Operators)'!$J$20) | L26: =L20-L25 -> 0 | M26: =IF(OR('Summary Op Stmt (Operators)'!$L$20=0,'Summary Op Stmt (Operators)'!$L$20=""),"",L26/'Summary Op Stmt (Operators)'!$L$20)
A27: Undistributed Operating Expenses
A28: Administrative and General | B28: ='Schedule 5 - Admin & General'!B65 -> 0 | C28: =IF(OR('Summary Op Stmt (Operators)'!$B$20=0,'Summary Op Stmt (Operators)'!$B$20=""),"",B28/'Summary Op Stmt (Operators)'!$B$20) | D28: ='Schedule 5 - Admin & General'!D65 -> 0 | E28: =IF(OR('Summary Op Stmt (Operators)'!$D$20=0,'Summary Op Stmt (Operators)'!$D$20=""),"",D28/'Summary Op Stmt (Operators)'!$D$20) | F28: ='Schedule 5 - Admin & General'!F65 -> 0 | G28: =IF(OR('Summary Op Stmt (Operators)'!$F$20=0,'Summary Op Stmt (Operators)'!$F$20=""),"",F28/'Summary Op Stmt (Operators)'!$F$20) | H28: ='Schedule 5 - Admin & General'!H65 -> 0 | I28: =IF(OR('Summary Op Stmt (Operators)'!$H$20=0,'Summary Op Stmt (Operators)'!$H$20=""),"",H28/'Summary Op Stmt (Operators)'!$H$20) | J28: ='Schedule 5 - Admin & General'!J65 -> 0 | K28: =IF(OR('Summary Op Stmt (Operators)'!$J$20=0,'Summary Op Stmt (Operators)'!$J$20=""),"",J28/'Summary Op Stmt (Operators)'!$J$20) | L28: ='Schedule 5 - Admin & General'!L65 -> 0 | M28: =IF(OR('Summary Op Stmt (Operators)'!$L$20=0,'Summary Op Stmt (Operators)'!$L$20=""),"",L28/'Summary Op Stmt (Operators)'!$L$20)
A29: Information and Telecommunications Systems | B29: ='Schedule 6 - Info & Telecom'!B68 -> 0 | C29: =IF(OR('Summary Op Stmt (Operators)'!$B$20=0,'Summary Op Stmt (Operators)'!$B$20=""),"",B29/'Summary Op Stmt (Operators)'!$B$20) | D29: ='Schedule 6 - Info & Telecom'!D68 -> 0 | E29: =IF(OR('Summary Op Stmt (Operators)'!$D$20=0,'Summary Op Stmt (Operators)'!$D$20=""),"",D29/'Summary Op Stmt (Operators)'!$D$20) | F29: ='Schedule 6 - Info & Telecom'!F68 -> 0 | G29: =IF(OR('Summary Op Stmt (Operators)'!$F$20=0,'Summary Op Stmt (Operators)'!$F$20=""),"",F29/'Summary Op Stmt (Operators)'!$F$20) | H29: ='Schedule 6 - Info & Telecom'!H68 -> 0 | I29: =IF(OR('Summary Op Stmt (Operators)'!$H$20=0,'Summary Op Stmt (Operators)'!$H$20=""),"",H29/'Summary Op Stmt (Operators)'!$H$20) | J29: ='Schedule 6 - Info & Telecom'!J68 -> 0 | K29: =IF(OR('Summary Op Stmt (Operators)'!$J$20=0,'Summary Op Stmt (Operators)'!$J$20=""),"",J29/'Summary Op Stmt (Operators)'!$J$20) | L29: ='Schedule 6 - Info & Telecom'!L68 -> 0 | M29: =IF(OR('Summary Op Stmt (Operators)'!$L$20=0,'Summary Op Stmt (Operators)'!$L$20=""),"",L29/'Summary Op Stmt (Operators)'!$L$20)
A30: Sales and Marketing | B30: ='Schedule 7 - Sales & Marketing'!B57 -> 0 | C30: =IF(OR('Summary Op Stmt (Operators)'!$B$20=0,'Summary Op Stmt (Operators)'!$B$20=""),"",B30/'Summary Op Stmt (Operators)'!$B$20) | D30: ='Schedule 7 - Sales & Marketing'!D57 -> 0 | E30: =IF(OR('Summary Op Stmt (Operators)'!$D$20=0,'Summary Op Stmt (Operators)'!$D$20=""),"",D30/'Summary Op Stmt (Operators)'!$D$20) | F30: ='Schedule 7 - Sales & Marketing'!F57 -> 0 | G30: =IF(OR('Summary Op Stmt (Operators)'!$F$20=0,'Summary Op Stmt (Operators)'!$F$20=""),"",F30/'Summary Op Stmt (Operators)'!$F$20) | H30: ='Schedule 7 - Sales & Marketing'!H57 -> 0 | I30: =IF(OR('Summary Op Stmt (Operators)'!$H$20=0,'Summary Op Stmt (Operators)'!$H$20=""),"",H30/'Summary Op Stmt (Operators)'!$H$20) | J30: ='Schedule 7 - Sales & Marketing'!J57 -> 0 | K30: =IF(OR('Summary Op Stmt (Operators)'!$J$20=0,'Summary Op Stmt (Operators)'!$J$20=""),"",J30/'Summary Op Stmt (Operators)'!$J$20) | L30: ='Schedule 7 - Sales & Marketing'!L57 -> 0 | M30: =IF(OR('Summary Op Stmt (Operators)'!$L$20=0,'Summary Op Stmt (Operators)'!$L$20=""),"",L30/'Summary Op Stmt (Operators)'!$L$20)
A31: Property Operation and Maintenance | B31: ='Schedule 8 - Prop Op & Maint'!B57 -> 0 | C31: =IF(OR('Summary Op Stmt (Operators)'!$B$20=0,'Summary Op Stmt (Operators)'!$B$20=""),"",B31/'Summary Op Stmt (Operators)'!$B$20) | D31: ='Schedule 8 - Prop Op & Maint'!D57 -> 0 | E31: =IF(OR('Summary Op Stmt (Operators)'!$D$20=0,'Summary Op Stmt (Operators)'!$D$20=""),"",D31/'Summary Op Stmt (Operators)'!$D$20) | F31: ='Schedule 8 - Prop Op & Maint'!F57 -> 0 | G31: =IF(OR('Summary Op Stmt (Operators)'!$F$20=0,'Summary Op Stmt (Operators)'!$F$20=""),"",F31/'Summary Op Stmt (Operators)'!$F$20) | H31: ='Schedule 8 - Prop Op & Maint'!H57 -> 0 | I31: =IF(OR('Summary Op Stmt (Operators)'!$H$20=0,'Summary Op Stmt (Operators)'!$H$20=""),"",H31/'Summary Op Stmt (Operators)'!$H$20) | J31: ='Schedule 8 - Prop Op & Maint'!J57 -> 0 | K31: =IF(OR('Summary Op Stmt (Operators)'!$J$20=0,'Summary Op Stmt (Operators)'!$J$20=""),"",J31/'Summary Op Stmt (Operators)'!$J$20) | L31: ='Schedule 8 - Prop Op & Maint'!L57 -> 0 | M31: =IF(OR('Summary Op Stmt (Operators)'!$L$20=0,'Summary Op Stmt (Operators)'!$L$20=""),"",L31/'Summary Op Stmt (Operators)'!$L$20)
A32: Utilities | B32: ='Schedule 9 - Utilities'!B16 -> 0 | C32: =IF(OR('Summary Op Stmt (Operators)'!$B$20=0,'Summary Op Stmt (Operators)'!$B$20=""),"",B32/'Summary Op Stmt (Operators)'!$B$20) | D32: ='Schedule 9 - Utilities'!D16 -> 0 | E32: =IF(OR('Summary Op Stmt (Operators)'!$D$20=0,'Summary Op Stmt (Operators)'!$D$20=""),"",D32/'Summary Op Stmt (Operators)'!$D$20) | F32: ='Schedule 9 - Utilities'!F16 -> 0 | G32: =IF(OR('Summary Op Stmt (Operators)'!$F$20=0,'Summary Op Stmt (Operators)'!$F$20=""),"",F32/'Summary Op Stmt (Operators)'!$F$20) | H32: ='Schedule 9 - Utilities'!H16 -> 0 | I32: =IF(OR('Summary Op Stmt (Operators)'!$H$20=0,'Summary Op Stmt (Operators)'!$H$20=""),"",H32/'Summary Op Stmt (Operators)'!$H$20) | J32: ='Schedule 9 - Utilities'!J16 -> 0 | K32: =IF(OR('Summary Op Stmt (Operators)'!$J$20=0,'Summary Op Stmt (Operators)'!$J$20=""),"",J32/'Summary Op Stmt (Operators)'!$J$20) | L32: ='Schedule 9 - Utilities'!L16 -> 0 | M32: =IF(OR('Summary Op Stmt (Operators)'!$L$20=0,'Summary Op Stmt (Operators)'!$L$20=""),"",L32/'Summary Op Stmt (Operators)'!$L$20)
A33: Total Undistributed Expenses | B33: =B28+B29+B30+B31+B32 -> 0 | C33: =IF(OR('Summary Op Stmt (Operators)'!$B$20=0,'Summary Op Stmt (Operators)'!$B$20=""),"",B33/'Summary Op Stmt (Operators)'!$B$20) | D33: =D28+D29+D30+D31+D32 -> 0 | E33: =IF(OR('Summary Op Stmt (Operators)'!$D$20=0,'Summary Op Stmt (Operators)'!$D$20=""),"",D33/'Summary Op Stmt (Operators)'!$D$20) | F33: =F28+F29+F30+F31+F32 -> 0 | G33: =IF(OR('Summary Op Stmt (Operators)'!$F$20=0,'Summary Op Stmt (Operators)'!$F$20=""),"",F33/'Summary Op Stmt (Operators)'!$F$20) | H33: =H28+H29+H30+H31+H32 -> 0 | I33: =IF(OR('Summary Op Stmt (Operators)'!$H$20=0,'Summary Op Stmt (Operators)'!$H$20=""),"",H33/'Summary Op Stmt (Operators)'!$H$20) | J33: =J28+J29+J30+J31+J32 -> 0 | K33: =IF(OR('Summary Op Stmt (Operators)'!$J$20=0,'Summary Op Stmt (Operators)'!$J$20=""),"",J33/'Summary Op Stmt (Operators)'!$J$20) | L33: =L28+L29+L30+L31+L32 -> 0 | M33: =IF(OR('Summary Op Stmt (Operators)'!$L$20=0,'Summary Op Stmt (Operators)'!$L$20=""),"",L33/'Summary Op Stmt (Operators)'!$L$20)
A34: Gross Operating Profit | B34: =B26-B33 -> 0 | C34: =IF(OR('Summary Op Stmt (Operators)'!$B$20=0,'Summary Op Stmt (Operators)'!$B$20=""),"",B34/'Summary Op Stmt (Operators)'!$B$20) | D34: =D26-D33 -> 0 | E34: =IF(OR('Summary Op Stmt (Operators)'!$D$20=0,'Summary Op Stmt (Operators)'!$D$20=""),"",D34/'Summary Op Stmt (Operators)'!$D$20) | F34: =F26-F33 -> 0 | G34: =IF(OR('Summary Op Stmt (Operators)'!$F$20=0,'Summary Op Stmt (Operators)'!$F$20=""),"",F34/'Summary Op Stmt (Operators)'!$F$20) | H34: =H26-H33 -> 0 | I34: =IF(OR('Summary Op Stmt (Operators)'!$H$20=0,'Summary Op Stmt (Operators)'!$H$20=""),"",H34/'Summary Op Stmt (Operators)'!$H$20) | J34: =J26-J33 -> 0 | K34: =IF(OR('Summary Op Stmt (Operators)'!$J$20=0,'Summary Op Stmt (Operators)'!$J$20=""),"",J34/'Summary Op Stmt (Operators)'!$J$20) | L34: =L26-L33 -> 0 | M34: =IF(OR('Summary Op Stmt (Operators)'!$L$20=0,'Summary Op Stmt (Operators)'!$L$20=""),"",L34/'Summary Op Stmt (Operators)'!$L$20)
A35: Management Fees | B35: ='Schedule 10 - Management Fees'!B10 -> 0 | C35: =IF(OR('Summary Op Stmt (Operators)'!$B$20=0,'Summary Op Stmt (Operators)'!$B$20=""),"",B35/'Summary Op Stmt (Operators)'!$B$20) | D35: ='Schedule 10 - Management Fees'!D10 -> 0 | E35: =IF(OR('Summary Op Stmt (Operators)'!$D$20=0,'Summary Op Stmt (Operators)'!$D$20=""),"",D35/'Summary Op Stmt (Operators)'!$D$20) | F35: ='Schedule 10 - Management Fees'!F10 -> 0 | G35: =IF(OR('Summary Op Stmt (Operators)'!$F$20=0,'Summary Op Stmt (Operators)'!$F$20=""),"",F35/'Summary Op Stmt (Operators)'!$F$20) | H35: ='Schedule 10 - Management Fees'!H10 -> 0 | I35: =IF(OR('Summary Op Stmt (Operators)'!$H$20=0,'Summary Op Stmt (Operators)'!$H$20=""),"",H35/'Summary Op Stmt (Operators)'!$H$20) | J35: ='Schedule 10 - Management Fees'!J10 -> 0 | K35: =IF(OR('Summary Op Stmt (Operators)'!$J$20=0,'Summary Op Stmt (Operators)'!$J$20=""),"",J35/'Summary Op Stmt (Operators)'!$J$20) | L35: ='Schedule 10 - Management Fees'!L10 -> 0 | M35: =IF(OR('Summary Op Stmt (Operators)'!$L$20=0,'Summary Op Stmt (Operators)'!$L$20=""),"",L35/'Summary Op Stmt (Operators)'!$L$20)
A36: Income Before Non-Operating Income and Expenses | B36: =B34-B35 -> 0 | C36: =IF(OR('Summary Op Stmt (Operators)'!$B$20=0,'Summary Op Stmt (Operators)'!$B$20=""),"",B36/'Summary Op Stmt (Operators)'!$B$20) | D36: =D34-D35 -> 0 | E36: =IF(OR('Summary Op Stmt (Operators)'!$D$20=0,'Summary Op Stmt (Operators)'!$D$20=""),"",D36/'Summary Op Stmt (Operators)'!$D$20) | F36: =F34-F35 -> 0 | G36: =IF(OR('Summary Op Stmt (Operators)'!$F$20=0,'Summary Op Stmt (Operators)'!$F$20=""),"",F36/'Summary Op Stmt (Operators)'!$F$20) | H36: =H34-H35 -> 0 | I36: =IF(OR('Summary Op Stmt (Operators)'!$H$20=0,'Summary Op Stmt (Operators)'!$H$20=""),"",H36/'Summary Op Stmt (Operators)'!$H$20) | J36: =J34-J35 -> 0 | K36: =IF(OR('Summary Op Stmt (Operators)'!$J$20=0,'Summary Op Stmt (Operators)'!$J$20=""),"",J36/'Summary Op Stmt (Operators)'!$J$20) | L36: =L34-L35 -> 0 | M36: =IF(OR('Summary Op Stmt (Operators)'!$L$20=0,'Summary Op Stmt (Operators)'!$L$20=""),"",L36/'Summary Op Stmt (Operators)'!$L$20)
A37: Non-Operating Income and Expenses
A38: Income | B38: ='Schedule 11 - Non-Operating'!B11 -> 0 | C38: =IF(OR('Summary Op Stmt (Operators)'!$B$20=0,'Summary Op Stmt (Operators)'!$B$20=""),"",B38/'Summary Op Stmt (Operators)'!$B$20) | D38: ='Schedule 11 - Non-Operating'!D11 -> 0 | E38: =IF(OR('Summary Op Stmt (Operators)'!$D$20=0,'Summary Op Stmt (Operators)'!$D$20=""),"",D38/'Summary Op Stmt (Operators)'!$D$20) | F38: ='Schedule 11 - Non-Operating'!F11 -> 0 | G38: =IF(OR('Summary Op Stmt (Operators)'!$F$20=0,'Summary Op Stmt (Operators)'!$F$20=""),"",F38/'Summary Op Stmt (Operators)'!$F$20) | H38: ='Schedule 11 - Non-Operating'!H11 -> 0 | I38: =IF(OR('Summary Op Stmt (Operators)'!$H$20=0,'Summary Op Stmt (Operators)'!$H$20=""),"",H38/'Summary Op Stmt (Operators)'!$H$20) | J38: ='Schedule 11 - Non-Operating'!J11 -> 0 | K38: =IF(OR('Summary Op Stmt (Operators)'!$J$20=0,'Summary Op Stmt (Operators)'!$J$20=""),"",J38/'Summary Op Stmt (Operators)'!$J$20) | L38: ='Schedule 11 - Non-Operating'!L11 -> 0 | M38: =IF(OR('Summary Op Stmt (Operators)'!$L$20=0,'Summary Op Stmt (Operators)'!$L$20=""),"",L38/'Summary Op Stmt (Operators)'!$L$20)
A39: Rent | B39: ='Schedule 11 - Non-Operating'!B15 -> 0 | C39: =IF(OR('Summary Op Stmt (Operators)'!$B$20=0,'Summary Op Stmt (Operators)'!$B$20=""),"",B39/'Summary Op Stmt (Operators)'!$B$20) | D39: ='Schedule 11 - Non-Operating'!D15 -> 0 | E39: =IF(OR('Summary Op Stmt (Operators)'!$D$20=0,'Summary Op Stmt (Operators)'!$D$20=""),"",D39/'Summary Op Stmt (Operators)'!$D$20) | F39: ='Schedule 11 - Non-Operating'!F15 -> 0 | G39: =IF(OR('Summary Op Stmt (Operators)'!$F$20=0,'Summary Op Stmt (Operators)'!$F$20=""),"",F39/'Summary Op Stmt (Operators)'!$F$20) | H39: ='Schedule 11 - Non-Operating'!H15 -> 0 | I39: =IF(OR('Summary Op Stmt (Operators)'!$H$20=0,'Summary Op Stmt (Operators)'!$H$20=""),"",H39/'Summary Op Stmt (Operators)'!$H$20) | J39: ='Schedule 11 - Non-Operating'!J15 -> 0 | K39: =IF(OR('Summary Op Stmt (Operators)'!$J$20=0,'Summary Op Stmt (Operators)'!$J$20=""),"",J39/'Summary Op Stmt (Operators)'!$J$20) | L39: ='Schedule 11 - Non-Operating'!L15 -> 0 | M39: =IF(OR('Summary Op Stmt (Operators)'!$L$20=0,'Summary Op Stmt (Operators)'!$L$20=""),"",L39/'Summary Op Stmt (Operators)'!$L$20)
A40: Property and Other Taxes | B40: ='Schedule 11 - Non-Operating'!B21 -> 0 | C40: =IF(OR('Summary Op Stmt (Operators)'!$B$20=0,'Summary Op Stmt (Operators)'!$B$20=""),"",B40/'Summary Op Stmt (Operators)'!$B$20) | D40: ='Schedule 11 - Non-Operating'!D21 -> 0 | E40: =IF(OR('Summary Op Stmt (Operators)'!$D$20=0,'Summary Op Stmt (Operators)'!$D$20=""),"",D40/'Summary Op Stmt (Operators)'!$D$20) | F40: ='Schedule 11 - Non-Operating'!F21 -> 0 | G40: =IF(OR('Summary Op Stmt (Operators)'!$F$20=0,'Summary Op Stmt (Operators)'!$F$20=""),"",F40/'Summary Op Stmt (Operators)'!$F$20) | H40: ='Schedule 11 - Non-Operating'!H21 -> 0 | I40: =IF(OR('Summary Op Stmt (Operators)'!$H$20=0,'Summary Op Stmt (Operators)'!$H$20=""),"",H40/'Summary Op Stmt (Operators)'!$H$20) | J40: ='Schedule 11 - Non-Operating'!J21 -> 0 | K40: =IF(OR('Summary Op Stmt (Operators)'!$J$20=0,'Summary Op Stmt (Operators)'!$J$20=""),"",J40/'Summary Op Stmt (Operators)'!$J$20) | L40: ='Schedule 11 - Non-Operating'!L21 -> 0 | M40: =IF(OR('Summary Op Stmt (Operators)'!$L$20=0,'Summary Op Stmt (Operators)'!$L$20=""),"",L40/'Summary Op Stmt (Operators)'!$L$20)
A41: Insurance | B41: ='Schedule 11 - Non-Operating'!B26 -> 0 | C41: =IF(OR('Summary Op Stmt (Operators)'!$B$20=0,'Summary Op Stmt (Operators)'!$B$20=""),"",B41/'Summary Op Stmt (Operators)'!$B$20) | D41: ='Schedule 11 - Non-Operating'!D26 -> 0 | E41: =IF(OR('Summary Op Stmt (Operators)'!$D$20=0,'Summary Op Stmt (Operators)'!$D$20=""),"",D41/'Summary Op Stmt (Operators)'!$D$20) | F41: ='Schedule 11 - Non-Operating'!F26 -> 0 | G41: =IF(OR('Summary Op Stmt (Operators)'!$F$20=0,'Summary Op Stmt (Operators)'!$F$20=""),"",F41/'Summary Op Stmt (Operators)'!$F$20) | H41: ='Schedule 11 - Non-Operating'!H26 -> 0 | I41: =IF(OR('Summary Op Stmt (Operators)'!$H$20=0,'Summary Op Stmt (Operators)'!$H$20=""),"",H41/'Summary Op Stmt (Operators)'!$H$20) | J41: ='Schedule 11 - Non-Operating'!J26 -> 0 | K41: =IF(OR('Summary Op Stmt (Operators)'!$J$20=0,'Summary Op Stmt (Operators)'!$J$20=""),"",J41/'Summary Op Stmt (Operators)'!$J$20) | L41: ='Schedule 11 - Non-Operating'!L26 -> 0 | M41: =IF(OR('Summary Op Stmt (Operators)'!$L$20=0,'Summary Op Stmt (Operators)'!$L$20=""),"",L41/'Summary Op Stmt (Operators)'!$L$20)
...

Sheet Summary Op Stmt (Owners)
A1: SUMMARY OPERATING STATEMENT [For Owners]
A2: Property: | B2: ='Setup & Assumptions'!$B$4 -> Enter property name | H2: Period / Year: | J2: ='Setup & Assumptions'!$B$5 -> e.g. January 2026 / FY2026
A3: Bottom line: Net Income. Revenue/expense % is of Total Operating Revenue; departmental expense % is of departmental revenue.
B4: Current Period | H4: Year-To-Date
B5: Actual | D5: Forecast / Budget | F5: Prior Year | H5: Actual | J5: Forecast / Budget | L5: Prior Year
A6: Line Item | B6: $ | C6: % | D6: $ | E6: % | F6: $ | G6: % | H6: $ | I6: % | J6: $ | K6: % | L6: $ | M6: %
A7: Operating Statistics
A8: Rooms Available
A9: Rooms Sold
A10: Occupancy % | B10: =IF(B8=0,"",B9/B8) | D10: =IF(D8=0,"",D9/D8) | F10: =IF(F8=0,"",F9/F8) | H10: =IF(H8=0,"",H9/H8) | J10: =IF(J8=0,"",J9/J8) | L10: =IF(L8=0,"",L9/L8)
A11: ADR (Average Daily Rate) | B11: =IF(B9=0,"",B16/B9) | D11: =IF(D9=0,"",D16/D9) | F11: =IF(F9=0,"",F16/F9) | H11: =IF(H9=0,"",H16/H9) | J11: =IF(J9=0,"",J16/J9) | L11: =IF(L9=0,"",L16/L9)
A12: Rooms RevPAR | B12: =IF(B8=0,"",B16/B8) | D12: =IF(D8=0,"",D16/D8) | F12: =IF(F8=0,"",F16/F8) | H12: =IF(H8=0,"",H16/H8) | J12: =IF(J8=0,"",J16/J8) | L12: =IF(L8=0,"",L16/L8)
A13: Total RevPAR | B13: =IF(B8=0,"",B20/B8) | D13: =IF(D8=0,"",D20/D8) | F13: =IF(F8=0,"",F20/F8) | H13: =IF(H8=0,"",H20/H8) | J13: =IF(J8=0,"",J20/J8) | L13: =IF(L8=0,"",L20/L8)
A15: Operating Revenue
A16: Rooms | B16: ='Schedule 1 - Rooms'!B25 -> 0 | C16: =IF(OR('Summary Op Stmt (Operators)'!$B$20=0,'Summary Op Stmt (Operators)'!$B$20=""),"",B16/'Summary Op Stmt (Operators)'!$B$20) | D16: ='Schedule 1 - Rooms'!D25 -> 0 | E16: =IF(OR('Summary Op Stmt (Operators)'!$D$20=0,'Summary Op Stmt (Operators)'!$D$20=""),"",D16/'Summary Op Stmt (Operators)'!$D$20) | F16: ='Schedule 1 - Rooms'!F25 -> 0 | G16: =IF(OR('Summary Op Stmt (Operators)'!$F$20=0,'Summary Op Stmt (Operators)'!$F$20=""),"",F16/'Summary Op Stmt (Operators)'!$F$20) | H16: ='Schedule 1 - Rooms'!H25 -> 0 | I16: =IF(OR('Summary Op Stmt (Operators)'!$H$20=0,'Summary Op Stmt (Operators)'!$H$20=""),"",H16/'Summary Op Stmt (Operators)'!$H$20) | J16: ='Schedule 1 - Rooms'!J25 -> 0 | K16: =IF(OR('Summary Op Stmt (Operators)'!$J$20=0,'Summary Op Stmt (Operators)'!$J$20=""),"",J16/'Summary Op Stmt (Operators)'!$J$20) | L16: ='Schedule 1 - Rooms'!L25 -> 0 | M16: =IF(OR('Summary Op Stmt (Operators)'!$L$20=0,'Summary Op Stmt (Operators)'!$L$20=""),"",L16/'Summary Op Stmt (Operators)'!$L$20)
A17: Food and Beverage | B17: ='Schedule 2 - Food & Beverage'!B32 -> 0 | C17: =IF(OR('Summary Op Stmt (Operators)'!$B$20=0,'Summary Op Stmt (Operators)'!$B$20=""),"",B17/'Summary Op Stmt (Operators)'!$B$20) | D17: ='Schedule 2 - Food & Beverage'!D32 -> 0 | E17: =IF(OR('Summary Op Stmt (Operators)'!$D$20=0,'Summary Op Stmt (Operators)'!$D$20=""),"",D17/'Summary Op Stmt (Operators)'!$D$20) | F17: ='Schedule 2 - Food & Beverage'!F32 -> 0 | G17: =IF(OR('Summary Op Stmt (Operators)'!$F$20=0,'Summary Op Stmt (Operators)'!$F$20=""),"",F17/'Summary Op Stmt (Operators)'!$F$20) | H17: ='Schedule 2 - Food & Beverage'!H32 -> 0 | I17: =IF(OR('Summary Op Stmt (Operators)'!$H$20=0,'Summary Op Stmt (Operators)'!$H$20=""),"",H17/'Summary Op Stmt (Operators)'!$H$20) | J17: ='Schedule 2 - Food & Beverage'!J32 -> 0 | K17: =IF(OR('Summary Op Stmt (Operators)'!$J$20=0,'Summary Op Stmt (Operators)'!$J$20=""),"",J17/'Summary Op Stmt (Operators)'!$J$20) | L17: ='Schedule 2 - Food & Beverage'!L32 -> 0 | M17: =IF(OR('Summary Op Stmt (Operators)'!$L$20=0,'Summary Op Stmt (Operators)'!$L$20=""),"",L17/'Summary Op Stmt (Operators)'!$L$20)
A18: Other Operated Departments | B18: ='Schedule 3 - Other Op Depts'!B13 -> 0 | C18: =IF(OR('Summary Op Stmt (Operators)'!$B$20=0,'Summary Op Stmt (Operators)'!$B$20=""),"",B18/'Summary Op Stmt (Operators)'!$B$20) | D18: ='Schedule 3 - Other Op Depts'!D13 -> 0 | E18: =IF(OR('Summary Op Stmt (Operators)'!$D$20=0,'Summary Op Stmt (Operators)'!$D$20=""),"",D18/'Summary Op Stmt (Operators)'!$D$20) | F18: ='Schedule 3 - Other Op Depts'!F13 -> 0 | G18: =IF(OR('Summary Op Stmt (Operators)'!$F$20=0,'Summary Op Stmt (Operators)'!$F$20=""),"",F18/'Summary Op Stmt (Operators)'!$F$20) | H18: ='Schedule 3 - Other Op Depts'!H13 -> 0 | I18: =IF(OR('Summary Op Stmt (Operators)'!$H$20=0,'Summary Op Stmt (Operators)'!$H$20=""),"",H18/'Summary Op Stmt (Operators)'!$H$20) | J18: ='Schedule 3 - Other Op Depts'!J13 -> 0 | K18: =IF(OR('Summary Op Stmt (Operators)'!$J$20=0,'Summary Op Stmt (Operators)'!$J$20=""),"",J18/'Summary Op Stmt (Operators)'!$J$20) | L18: ='Schedule 3 - Other Op Depts'!L13 -> 0 | M18: =IF(OR('Summary Op Stmt (Operators)'!$L$20=0,'Summary Op Stmt (Operators)'!$L$20=""),"",L18/'Summary Op Stmt (Operators)'!$L$20)
A19: Miscellaneous Income | B19: ='Schedule 4 - Misc Income'!B22 -> 0 | C19: =IF(OR('Summary Op Stmt (Operators)'!$B$20=0,'Summary Op Stmt (Operators)'!$B$20=""),"",B19/'Summary Op Stmt (Operators)'!$B$20) | D19: ='Schedule 4 - Misc Income'!D22 -> 0 | E19: =IF(OR('Summary Op Stmt (Operators)'!$D$20=0,'Summary Op Stmt (Operators)'!$D$20=""),"",D19/'Summary Op Stmt (Operators)'!$D$20) | F19: ='Schedule 4 - Misc Income'!F22 -> 0 | G19: =IF(OR('Summary Op Stmt (Operators)'!$F$20=0,'Summary Op Stmt (Operators)'!$F$20=""),"",F19/'Summary Op Stmt (Operators)'!$F$20) | H19: ='Schedule 4 - Misc Income'!H22 -> 0 | I19: =IF(OR('Summary Op Stmt (Operators)'!$H$20=0,'Summary Op Stmt (Operators)'!$H$20=""),"",H19/'Summary Op Stmt (Operators)'!$H$20) | J19: ='Schedule 4 - Misc Income'!J22 -> 0 | K19: =IF(OR('Summary Op Stmt (Operators)'!$J$20=0,'Summary Op Stmt (Operators)'!$J$20=""),"",J19/'Summary Op Stmt (Operators)'!$J$20) | L19: ='Schedule 4 - Misc Income'!L22 -> 0 | M19: =IF(OR('Summary Op Stmt (Operators)'!$L$20=0,'Summary Op Stmt (Operators)'!$L$20=""),"",L19/'Summary Op Stmt (Operators)'!$L$20)
A20: Total Operating Revenue | B20: =B16+B17+B18+B19 -> 0 | C20: =IF(OR('Summary Op Stmt (Operators)'!$B$20=0,'Summary Op Stmt (Operators)'!$B$20=""),"",B20/'Summary Op Stmt (Operators)'!$B$20) | D20: =D16+D17+D18+D19 -> 0 | E20: =IF(OR('Summary Op Stmt (Operators)'!$D$20=0,'Summary Op Stmt (Operators)'!$D$20=""),"",D20/'Summary Op Stmt (Operators)'!$D$20) | F20: =F16+F17+F18+F19 -> 0 | G20: =IF(OR('Summary Op Stmt (Operators)'!$F$20=0,'Summary Op Stmt (Operators)'!$F$20=""),"",F20/'Summary Op Stmt (Operators)'!$F$20) | H20: =H16+H17+H18+H19 -> 0 | I20: =IF(OR('Summary Op Stmt (Operators)'!$H$20=0,'Summary Op Stmt (Operators)'!$H$20=""),"",H20/'Summary Op Stmt (Operators)'!$H$20) | J20: =J16+J17+J18+J19 -> 0 | K20: =IF(OR('Summary Op Stmt (Operators)'!$J$20=0,'Summary Op Stmt (Operators)'!$J$20=""),"",J20/'Summary Op Stmt (Operators)'!$J$20) | L20: =L16+L17+L18+L19 -> 0 | M20: =IF(OR('Summary Op Stmt (Operators)'!$L$20=0,'Summary Op Stmt (Operators)'!$L$20=""),"",L20/'Summary Op Stmt (Operators)'!$L$20)
A21: Departmental Expenses
A22: Rooms | B22: ='Schedule 1 - Rooms'!B81 -> 0 | C22: =IF(OR(B16=0,B16=""),"",B22/B16) | D22: ='Schedule 1 - Rooms'!D81 -> 0 | E22: =IF(OR(D16=0,D16=""),"",D22/D16) | F22: ='Schedule 1 - Rooms'!F81 -> 0 | G22: =IF(OR(F16=0,F16=""),"",F22/F16) | H22: ='Schedule 1 - Rooms'!H81 -> 0 | I22: =IF(OR(H16=0,H16=""),"",H22/H16) | J22: ='Schedule 1 - Rooms'!J81 -> 0 | K22: =IF(OR(J16=0,J16=""),"",J22/J16) | L22: ='Schedule 1 - Rooms'!L81 -> 0 | M22: =IF(OR(L16=0,L16=""),"",L22/L16)
A23: Food and Beverage | B23: ='Schedule 2 - Food & Beverage'!B42+'Schedule 2 - Food & Beverage'!B105 -> 0 | C23: =IF(OR(B17=0,B17=""),"",B23/B17) | D23: ='Schedule 2 - Food & Beverage'!D42+'Schedule 2 - Food & Beverage'!D105 -> 0 | E23: =IF(OR(D17=0,D17=""),"",D23/D17) | F23: ='Schedule 2 - Food & Beverage'!F42+'Schedule 2 - Food & Beverage'!F105 -> 0 | G23: =IF(OR(F17=0,F17=""),"",F23/F17) | H23: ='Schedule 2 - Food & Beverage'!H42+'Schedule 2 - Food & Beverage'!H105 -> 0 | I23: =IF(OR(H17=0,H17=""),"",H23/H17) | J23: ='Schedule 2 - Food & Beverage'!J42+'Schedule 2 - Food & Beverage'!J105 -> 0 | K23: =IF(OR(J17=0,J17=""),"",J23/J17) | L23: ='Schedule 2 - Food & Beverage'!L42+'Schedule 2 - Food & Beverage'!L105 -> 0 | M23: =IF(OR(L17=0,L17=""),"",L23/L17)
A24: Other Operated Departments | B24: ='Schedule 3 - Other Op Depts'!B20 -> 0 | C24: =IF(OR(B18=0,B18=""),"",B24/B18) | D24: ='Schedule 3 - Other Op Depts'!D20 -> 0 | E24: =IF(OR(D18=0,D18=""),"",D24/D18) | F24: ='Schedule 3 - Other Op Depts'!F20 -> 0 | G24: =IF(OR(F18=0,F18=""),"",F24/F18) | H24: ='Schedule 3 - Other Op Depts'!H20 -> 0 | I24: =IF(OR(H18=0,H18=""),"",H24/H18) | J24: ='Schedule 3 - Other Op Depts'!J20 -> 0 | K24: =IF(OR(J18=0,J18=""),"",J24/J18) | L24: ='Schedule 3 - Other Op Depts'!L20 -> 0 | M24: =IF(OR(L18=0,L18=""),"",L24/L18)
A25: Total Departmental Expenses | B25: =B22+B23+B24 -> 0 | C25: =IF(OR('Summary Op Stmt (Operators)'!$B$20=0,'Summary Op Stmt (Operators)'!$B$20=""),"",B25/'Summary Op Stmt (Operators)'!$B$20) | D25: =D22+D23+D24 -> 0 | E25: =IF(OR('Summary Op Stmt (Operators)'!$D$20=0,'Summary Op Stmt (Operators)'!$D$20=""),"",D25/'Summary Op Stmt (Operators)'!$D$20) | F25: =F22+F23+F24 -> 0 | G25: =IF(OR('Summary Op Stmt (Operators)'!$F$20=0,'Summary Op Stmt (Operators)'!$F$20=""),"",F25/'Summary Op Stmt (Operators)'!$F$20) | H25: =H22+H23+H24 -> 0 | I25: =IF(OR('Summary Op Stmt (Operators)'!$H$20=0,'Summary Op Stmt (Operators)'!$H$20=""),"",H25/'Summary Op Stmt (Operators)'!$H$20) | J25: =J22+J23+J24 -> 0 | K25: =IF(OR('Summary Op Stmt (Operators)'!$J$20=0,'Summary Op Stmt (Operators)'!$J$20=""),"",J25/'Summary Op Stmt (Operators)'!$J$20) | L25: =L22+L23+L24 -> 0 | M25: =IF(OR('Summary Op Stmt (Operators)'!$L$20=0,'Summary Op Stmt (Operators)'!$L$20=""),"",L25/'Summary Op Stmt (Operators)'!$L$20)
A26: Total Departmental Profit | B26: =B20-B25 -> 0 | C26: =IF(OR('Summary Op Stmt (Operators)'!$B$20=0,'Summary Op Stmt (Operators)'!$B$20=""),"",B26/'Summary Op Stmt (Operators)'!$B$20) | D26: =D20-D25 -> 0 | E26: =IF(OR('Summary Op Stmt (Operators)'!$D$20=0,'Summary Op Stmt (Operators)'!$D$20=""),"",D26/'Summary Op Stmt (Operators)'!$D$20) | F26: =F20-F25 -> 0 | G26: =IF(OR('Summary Op Stmt (Operators)'!$F$20=0,'Summary Op Stmt (Operators)'!$F$20=""),"",F26/'Summary Op Stmt (Operators)'!$F$20) | H26: =H20-H25 -> 0 | I26: =IF(OR('Summary Op Stmt (Operators)'!$H$20=0,'Summary Op Stmt (Operators)'!$H$20=""),"",H26/'Summary Op Stmt (Operators)'!$H$20) | J26: =J20-J25 -> 0 | K26: =IF(OR('Summary Op Stmt (Operators)'!$J$20=0,'Summary Op Stmt (Operators)'!$J$20=""),"",J26/'Summary Op Stmt (Operators)'!$J$20) | L26: =L20-L25 -> 0 | M26: =IF(OR('Summary Op Stmt (Operators)'!$L$20=0,'Summary Op Stmt (Operators)'!$L$20=""),"",L26/'Summary Op Stmt (Operators)'!$L$20)
A27: Undistributed Operating Expenses
A28: Administrative and General | B28: ='Schedule 5 - Admin & General'!B65 -> 0 | C28: =IF(OR('Summary Op Stmt (Operators)'!$B$20=0,'Summary Op Stmt (Operators)'!$B$20=""),"",B28/'Summary Op Stmt (Operators)'!$B$20) | D28: ='Schedule 5 - Admin & General'!D65 -> 0 | E28: =IF(OR('Summary Op Stmt (Operators)'!$D$20=0,'Summary Op Stmt (Operators)'!$D$20=""),"",D28/'Summary Op Stmt (Operators)'!$D$20) | F28: ='Schedule 5 - Admin & General'!F65 -> 0 | G28: =IF(OR('Summary Op Stmt (Operators)'!$F$20=0,'Summary Op Stmt (Operators)'!$F$20=""),"",F28/'Summary Op Stmt (Operators)'!$F$20) | H28: ='Schedule 5 - Admin & General'!H65 -> 0 | I28: =IF(OR('Summary Op Stmt (Operators)'!$H$20=0,'Summary Op Stmt (Operators)'!$H$20=""),"",H28/'Summary Op Stmt (Operators)'!$H$20) | J28: ='Schedule 5 - Admin & General'!J65 -> 0 | K28: =IF(OR('Summary Op Stmt (Operators)'!$J$20=0,'Summary Op Stmt (Operators)'!$J$20=""),"",J28/'Summary Op Stmt (Operators)'!$J$20) | L28: ='Schedule 5 - Admin & General'!L65 -> 0 | M28: =IF(OR('Summary Op Stmt (Operators)'!$L$20=0,'Summary Op Stmt (Operators)'!$L$20=""),"",L28/'Summary Op Stmt (Operators)'!$L$20)
A29: Information and Telecommunications Systems | B29: ='Schedule 6 - Info & Telecom'!B68 -> 0 | C29: =IF(OR('Summary Op Stmt (Operators)'!$B$20=0,'Summary Op Stmt (Operators)'!$B$20=""),"",B29/'Summary Op Stmt (Operators)'!$B$20) | D29: ='Schedule 6 - Info & Telecom'!D68 -> 0 | E29: =IF(OR('Summary Op Stmt (Operators)'!$D$20=0,'Summary Op Stmt (Operators)'!$D$20=""),"",D29/'Summary Op Stmt (Operators)'!$D$20) | F29: ='Schedule 6 - Info & Telecom'!F68 -> 0 | G29: =IF(OR('Summary Op Stmt (Operators)'!$F$20=0,'Summary Op Stmt (Operators)'!$F$20=""),"",F29/'Summary Op Stmt (Operators)'!$F$20) | H29: ='Schedule 6 - Info & Telecom'!H68 -> 0 | I29: =IF(OR('Summary Op Stmt (Operators)'!$H$20=0,'Summary Op Stmt (Operators)'!$H$20=""),"",H29/'Summary Op Stmt (Operators)'!$H$20) | J29: ='Schedule 6 - Info & Telecom'!J68 -> 0 | K29: =IF(OR('Summary Op Stmt (Operators)'!$J$20=0,'Summary Op Stmt (Operators)'!$J$20=""),"",J29/'Summary Op Stmt (Operators)'!$J$20) | L29: ='Schedule 6 - Info & Telecom'!L68 -> 0 | M29: =IF(OR('Summary Op Stmt (Operators)'!$L$20=0,'Summary Op Stmt (Operators)'!$L$20=""),"",L29/'Summary Op Stmt (Operators)'!$L$20)
A30: Sales and Marketing | B30: ='Schedule 7 - Sales & Marketing'!B57 -> 0 | C30: =IF(OR('Summary Op Stmt (Operators)'!$B$20=0,'Summary Op Stmt (Operators)'!$B$20=""),"",B30/'Summary Op Stmt (Operators)'!$B$20) | D30: ='Schedule 7 - Sales & Marketing'!D57 -> 0 | E30: =IF(OR('Summary Op Stmt (Operators)'!$D$20=0,'Summary Op Stmt (Operators)'!$D$20=""),"",D30/'Summary Op Stmt (Operators)'!$D$20) | F30: ='Schedule 7 - Sales & Marketing'!F57 -> 0 | G30: =IF(OR('Summary Op Stmt (Operators)'!$F$20=0,'Summary Op Stmt (Operators)'!$F$20=""),"",F30/'Summary Op Stmt (Operators)'!$F$20) | H30: ='Schedule 7 - Sales & Marketing'!H57 -> 0 | I30: =IF(OR('Summary Op Stmt (Operators)'!$H$20=0,'Summary Op Stmt (Operators)'!$H$20=""),"",H30/'Summary Op Stmt (Operators)'!$H$20) | J30: ='Schedule 7 - Sales & Marketing'!J57 -> 0 | K30: =IF(OR('Summary Op Stmt (Operators)'!$J$20=0,'Summary Op Stmt (Operators)'!$J$20=""),"",J30/'Summary Op Stmt (Operators)'!$J$20) | L30: ='Schedule 7 - Sales & Marketing'!L57 -> 0 | M30: =IF(OR('Summary Op Stmt (Operators)'!$L$20=0,'Summary Op Stmt (Operators)'!$L$20=""),"",L30/'Summary Op Stmt (Operators)'!$L$20)
A31: Property Operation and Maintenance | B31: ='Schedule 8 - Prop Op & Maint'!B57 -> 0 | C31: =IF(OR('Summary Op Stmt (Operators)'!$B$20=0,'Summary Op Stmt (Operators)'!$B$20=""),"",B31/'Summary Op Stmt (Operators)'!$B$20) | D31: ='Schedule 8 - Prop Op & Maint'!D57 -> 0 | E31: =IF(OR('Summary Op Stmt (Operators)'!$D$20=0,'Summary Op Stmt (Operators)'!$D$20=""),"",D31/'Summary Op Stmt (Operators)'!$D$20) | F31: ='Schedule 8 - Prop Op & Maint'!F57 -> 0 | G31: =IF(OR('Summary Op Stmt (Operators)'!$F$20=0,'Summary Op Stmt (Operators)'!$F$20=""),"",F31/'Summary Op Stmt (Operators)'!$F$20) | H31: ='Schedule 8 - Prop Op & Maint'!H57 -> 0 | I31: =IF(OR('Summary Op Stmt (Operators)'!$H$20=0,'Summary Op Stmt (Operators)'!$H$20=""),"",H31/'Summary Op Stmt (Operators)'!$H$20) | J31: ='Schedule 8 - Prop Op & Maint'!J57 -> 0 | K31: =IF(OR('Summary Op Stmt (Operators)'!$J$20=0,'Summary Op Stmt (Operators)'!$J$20=""),"",J31/'Summary Op Stmt (Operators)'!$J$20) | L31: ='Schedule 8 - Prop Op & Maint'!L57 -> 0 | M31: =IF(OR('Summary Op Stmt (Operators)'!$L$20=0,'Summary Op Stmt (Operators)'!$L$20=""),"",L31/'Summary Op Stmt (Operators)'!$L$20)
A32: Utilities | B32: ='Schedule 9 - Utilities'!B16 -> 0 | C32: =IF(OR('Summary Op Stmt (Operators)'!$B$20=0,'Summary Op Stmt (Operators)'!$B$20=""),"",B32/'Summary Op Stmt (Operators)'!$B$20) | D32: ='Schedule 9 - Utilities'!D16 -> 0 | E32: =IF(OR('Summary Op Stmt (Operators)'!$D$20=0,'Summary Op Stmt (Operators)'!$D$20=""),"",D32/'Summary Op Stmt (Operators)'!$D$20) | F32: ='Schedule 9 - Utilities'!F16 -> 0 | G32: =IF(OR('Summary Op Stmt (Operators)'!$F$20=0,'Summary Op Stmt (Operators)'!$F$20=""),"",F32/'Summary Op Stmt (Operators)'!$F$20) | H32: ='Schedule 9 - Utilities'!H16 -> 0 | I32: =IF(OR('Summary Op Stmt (Operators)'!$H$20=0,'Summary Op Stmt (Operators)'!$H$20=""),"",H32/'Summary Op Stmt (Operators)'!$H$20) | J32: ='Schedule 9 - Utilities'!J16 -> 0 | K32: =IF(OR('Summary Op Stmt (Operators)'!$J$20=0,'Summary Op Stmt (Operators)'!$J$20=""),"",J32/'Summary Op Stmt (Operators)'!$J$20) | L32: ='Schedule 9 - Utilities'!L16 -> 0 | M32: =IF(OR('Summary Op Stmt (Operators)'!$L$20=0,'Summary Op Stmt (Operators)'!$L$20=""),"",L32/'Summary Op Stmt (Operators)'!$L$20)
A33: Total Undistributed Expenses | B33: =B28+B29+B30+B31+B32 -> 0 | C33: =IF(OR('Summary Op Stmt (Operators)'!$B$20=0,'Summary Op Stmt (Operators)'!$B$20=""),"",B33/'Summary Op Stmt (Operators)'!$B$20) | D33: =D28+D29+D30+D31+D32 -> 0 | E33: =IF(OR('Summary Op Stmt (Operators)'!$D$20=0,'Summary Op Stmt (Operators)'!$D$20=""),"",D33/'Summary Op Stmt (Operators)'!$D$20) | F33: =F28+F29+F30+F31+F32 -> 0 | G33: =IF(OR('Summary Op Stmt (Operators)'!$F$20=0,'Summary Op Stmt (Operators)'!$F$20=""),"",F33/'Summary Op Stmt (Operators)'!$F$20) | H33: =H28+H29+H30+H31+H32 -> 0 | I33: =IF(OR('Summary Op Stmt (Operators)'!$H$20=0,'Summary Op Stmt (Operators)'!$H$20=""),"",H33/'Summary Op Stmt (Operators)'!$H$20) | J33: =J28+J29+J30+J31+J32 -> 0 | K33: =IF(OR('Summary Op Stmt (Operators)'!$J$20=0,'Summary Op Stmt (Operators)'!$J$20=""),"",J33/'Summary Op Stmt (Operators)'!$J$20) | L33: =L28+L29+L30+L31+L32 -> 0 | M33: =IF(OR('Summary Op Stmt (Operators)'!$L$20=0,'Summary Op Stmt (Operators)'!$L$20=""),"",L33/'Summary Op Stmt (Operators)'!$L$20)
A34: Gross Operating Profit | B34: =B26-B33 -> 0 | C34: =IF(OR('Summary Op Stmt (Operators)'!$B$20=0,'Summary Op Stmt (Operators)'!$B$20=""),"",B34/'Summary Op Stmt (Operators)'!$B$20) | D34: =D26-D33 -> 0 | E34: =IF(OR('Summary Op Stmt (Operators)'!$D$20=0,'Summary Op Stmt (Operators)'!$D$20=""),"",D34/'Summary Op Stmt (Operators)'!$D$20) | F34: =F26-F33 -> 0 | G34: =IF(OR('Summary Op Stmt (Operators)'!$F$20=0,'Summary Op Stmt (Operators)'!$F$20=""),"",F34/'Summary Op Stmt (Operators)'!$F$20) | H34: =H26-H33 -> 0 | I34: =IF(OR('Summary Op Stmt (Operators)'!$H$20=0,'Summary Op Stmt (Operators)'!$H$20=""),"",H34/'Summary Op Stmt (Operators)'!$H$20) | J34: =J26-J33 -> 0 | K34: =IF(OR('Summary Op Stmt (Operators)'!$J$20=0,'Summary Op Stmt (Operators)'!$J$20=""),"",J34/'Summary Op Stmt (Operators)'!$J$20) | L34: =L26-L33 -> 0 | M34: =IF(OR('Summary Op Stmt (Operators)'!$L$20=0,'Summary Op Stmt (Operators)'!$L$20=""),"",L34/'Summary Op Stmt (Operators)'!$L$20)
A35: Management Fees | B35: ='Schedule 10 - Management Fees'!B10 -> 0 | C35: =IF(OR('Summary Op Stmt (Operators)'!$B$20=0,'Summary Op Stmt (Operators)'!$B$20=""),"",B35/'Summary Op Stmt (Operators)'!$B$20) | D35: ='Schedule 10 - Management Fees'!D10 -> 0 | E35: =IF(OR('Summary Op Stmt (Operators)'!$D$20=0,'Summary Op Stmt (Operators)'!$D$20=""),"",D35/'Summary Op Stmt (Operators)'!$D$20) | F35: ='Schedule 10 - Management Fees'!F10 -> 0 | G35: =IF(OR('Summary Op Stmt (Operators)'!$F$20=0,'Summary Op Stmt (Operators)'!$F$20=""),"",F35/'Summary Op Stmt (Operators)'!$F$20) | H35: ='Schedule 10 - Management Fees'!H10 -> 0 | I35: =IF(OR('Summary Op Stmt (Operators)'!$H$20=0,'Summary Op Stmt (Operators)'!$H$20=""),"",H35/'Summary Op Stmt (Operators)'!$H$20) | J35: ='Schedule 10 - Management Fees'!J10 -> 0 | K35: =IF(OR('Summary Op Stmt (Operators)'!$J$20=0,'Summary Op Stmt (Operators)'!$J$20=""),"",J35/'Summary Op Stmt (Operators)'!$J$20) | L35: ='Schedule 10 - Management Fees'!L10 -> 0 | M35: =IF(OR('Summary Op Stmt (Operators)'!$L$20=0,'Summary Op Stmt (Operators)'!$L$20=""),"",L35/'Summary Op Stmt (Operators)'!$L$20)
A36: Income Before Non-Operating Income and Expenses | B36: =B34-B35 -> 0 | C36: =IF(OR('Summary Op Stmt (Operators)'!$B$20=0,'Summary Op Stmt (Operators)'!$B$20=""),"",B36/'Summary Op Stmt (Operators)'!$B$20) | D36: =D34-D35 -> 0 | E36: =IF(OR('Summary Op Stmt (Operators)'!$D$20=0,'Summary Op Stmt (Operators)'!$D$20=""),"",D36/'Summary Op Stmt (Operators)'!$D$20) | F36: =F34-F35 -> 0 | G36: =IF(OR('Summary Op Stmt (Operators)'!$F$20=0,'Summary Op Stmt (Operators)'!$F$20=""),"",F36/'Summary Op Stmt (Operators)'!$F$20) | H36: =H34-H35 -> 0 | I36: =IF(OR('Summary Op Stmt (Operators)'!$H$20=0,'Summary Op Stmt (Operators)'!$H$20=""),"",H36/'Summary Op Stmt (Operators)'!$H$20) | J36: =J34-J35 -> 0 | K36: =IF(OR('Summary Op Stmt (Operators)'!$J$20=0,'Summary Op Stmt (Operators)'!$J$20=""),"",J36/'Summary Op Stmt (Operators)'!$J$20) | L36: =L34-L35 -> 0 | M36: =IF(OR('Summary Op Stmt (Operators)'!$L$20=0,'Summary Op Stmt (Operators)'!$L$20=""),"",L36/'Summary Op Stmt (Operators)'!$L$20)
A37: Non-Operating Income and Expenses
A38: Income | B38: ='Schedule 11 - Non-Operating'!B11 -> 0 | C38: =IF(OR('Summary Op Stmt (Operators)'!$B$20=0,'Summary Op Stmt (Operators)'!$B$20=""),"",B38/'Summary Op Stmt (Operators)'!$B$20) | D38: ='Schedule 11 - Non-Operating'!D11 -> 0 | E38: =IF(OR('Summary Op Stmt (Operators)'!$D$20=0,'Summary Op Stmt (Operators)'!$D$20=""),"",D38/'Summary Op Stmt (Operators)'!$D$20) | F38: ='Schedule 11 - Non-Operating'!F11 -> 0 | G38: =IF(OR('Summary Op Stmt (Operators)'!$F$20=0,'Summary Op Stmt (Operators)'!$F$20=""),"",F38/'Summary Op Stmt (Operators)'!$F$20) | H38: ='Schedule 11 - Non-Operating'!H11 -> 0 | I38: =IF(OR('Summary Op Stmt (Operators)'!$H$20=0,'Summary Op Stmt (Operators)'!$H$20=""),"",H38/'Summary Op Stmt (Operators)'!$H$20) | J38: ='Schedule 11 - Non-Operating'!J11 -> 0 | K38: =IF(OR('Summary Op Stmt (Operators)'!$J$20=0,'Summary Op Stmt (Operators)'!$J$20=""),"",J38/'Summary Op Stmt (Operators)'!$J$20) | L38: ='Schedule 11 - Non-Operating'!L11 -> 0 | M38: =IF(OR('Summary Op Stmt (Operators)'!$L$20=0,'Summary Op Stmt (Operators)'!$L$20=""),"",L38/'Summary Op Stmt (Operators)'!$L$20)
A39: Rent | B39: ='Schedule 11 - Non-Operating'!B15 -> 0 | C39: =IF(OR('Summary Op Stmt (Operators)'!$B$20=0,'Summary Op Stmt (Operators)'!$B$20=""),"",B39/'Summary Op Stmt (Operators)'!$B$20) | D39: ='Schedule 11 - Non-Operating'!D15 -> 0 | E39: =IF(OR('Summary Op Stmt (Operators)'!$D$20=0,'Summary Op Stmt (Operators)'!$D$20=""),"",D39/'Summary Op Stmt (Operators)'!$D$20) | F39: ='Schedule 11 - Non-Operating'!F15 -> 0 | G39: =IF(OR('Summary Op Stmt (Operators)'!$F$20=0,'Summary Op Stmt (Operators)'!$F$20=""),"",F39/'Summary Op Stmt (Operators)'!$F$20) | H39: ='Schedule 11 - Non-Operating'!H15 -> 0 | I39: =IF(OR('Summary Op Stmt (Operators)'!$H$20=0,'Summary Op Stmt (Operators)'!$H$20=""),"",H39/'Summary Op Stmt (Operators)'!$H$20) | J39: ='Schedule 11 - Non-Operating'!J15 -> 0 | K39: =IF(OR('Summary Op Stmt (Operators)'!$J$20=0,'Summary Op Stmt (Operators)'!$J$20=""),"",J39/'Summary Op Stmt (Operators)'!$J$20) | L39: ='Schedule 11 - Non-Operating'!L15 -> 0 | M39: =IF(OR('Summary Op Stmt (Operators)'!$L$20=0,'Summary Op Stmt (Operators)'!$L$20=""),"",L39/'Summary Op Stmt (Operators)'!$L$20)
A40: Property and Other Taxes | B40: ='Schedule 11 - Non-Operating'!B21 -> 0 | C40: =IF(OR('Summary Op Stmt (Operators)'!$B$20=0,'Summary Op Stmt (Operators)'!$B$20=""),"",B40/'Summary Op Stmt (Operators)'!$B$20) | D40: ='Schedule 11 - Non-Operating'!D21 -> 0 | E40: =IF(OR('Summary Op Stmt (Operators)'!$D$20=0,'Summary Op Stmt (Operators)'!$D$20=""),"",D40/'Summary Op Stmt (Operators)'!$D$20) | F40: ='Schedule 11 - Non-Operating'!F21 -> 0 | G40: =IF(OR('Summary Op Stmt (Operators)'!$F$20=0,'Summary Op Stmt (Operators)'!$F$20=""),"",F40/'Summary Op Stmt (Operators)'!$F$20) | H40: ='Schedule 11 - Non-Operating'!H21 -> 0 | I40: =IF(OR('Summary Op Stmt (Operators)'!$H$20=0,'Summary Op Stmt (Operators)'!$H$20=""),"",H40/'Summary Op Stmt (Operators)'!$H$20) | J40: ='Schedule 11 - Non-Operating'!J21 -> 0 | K40: =IF(OR('Summary Op Stmt (Operators)'!$J$20=0,'Summary Op Stmt (Operators)'!$J$20=""),"",J40/'Summary Op Stmt (Operators)'!$J$20) | L40: ='Schedule 11 - Non-Operating'!L21 -> 0 | M40: =IF(OR('Summary Op Stmt (Operators)'!$L$20=0,'Summary Op Stmt (Operators)'!$L$20=""),"",L40/'Summary Op Stmt (Operators)'!$L$20)
A41: Insurance | B41: ='Schedule 11 - Non-Operating'!B26 -> 0 | C41: =IF(OR('Summary Op Stmt (Operators)'!$B$20=0,'Summary Op Stmt (Operators)'!$B$20=""),"",B41/'Summary Op Stmt (Operators)'!$B$20) | D41: ='Schedule 11 - Non-Operating'!D26 -> 0 | E41: =IF(OR('Summary Op Stmt (Operators)'!$D$20=0,'Summary Op Stmt (Operators)'!$D$20=""),"",D41/'Summary Op Stmt (Operators)'!$D$20) | F41: ='Schedule 11 - Non-Operating'!F26 -> 0 | G41: =IF(OR('Summary Op Stmt (Operators)'!$F$20=0,'Summary Op Stmt (Operators)'!$F$20=""),"",F41/'Summary Op Stmt (Operators)'!$F$20) | H41: ='Schedule 11 - Non-Operating'!H26 -> 0 | I41: =IF(OR('Summary Op Stmt (Operators)'!$H$20=0,'Summary Op Stmt (Operators)'!$H$20=""),"",H41/'Summary Op Stmt (Operators)'!$H$20) | J41: ='Schedule 11 - Non-Operating'!J26 -> 0 | K41: =IF(OR('Summary Op Stmt (Operators)'!$J$20=0,'Summary Op Stmt (Operators)'!$J$20=""),"",J41/'Summary Op Stmt (Operators)'!$J$20) | L41: ='Schedule 11 - Non-Operating'!L26 -> 0 | M41: =IF(OR('Summary Op Stmt (Operators)'!$L$20=0,'Summary Op Stmt (Operators)'!$L$20=""),"",L41/'Summary Op Stmt (Operators)'!$L$20)
...

Sheet Schedule 1 - Rooms
A1: ROOMS — SCHEDULE 1
A2: Property: | B2: ='Setup & Assumptions'!$B$4 -> Enter property name | H2: Period / Year: | J2: ='Setup & Assumptions'!$B$5 -> e.g. January 2026 / FY2026
A3: Departmental percentages are calculated on Total Rooms Revenue.
B4: Current Period | H4: Year-To-Date
B5: Actual | D5: Forecast / Budget | F5: Prior Year | H5: Actual | J5: Forecast / Budget | L5: Prior Year
A6: Line Item | B6: $ | C6: % | D6: $ | E6: % | F6: $ | G6: % | H6: $ | I6: % | J6: $ | K6: % | L6: $ | M6: %
A7: Revenue
A8: Transient Rooms Revenue
A9: Retail | C9: =IF(OR(B25=0,B25=""),"",B9/B25) | E9: =IF(OR(D25=0,D25=""),"",D9/D25) | G9: =IF(OR(F25=0,F25=""),"",F9/F25) | I9: =IF(OR(H25=0,H25=""),"",H9/H25) | K9: =IF(OR(J25=0,J25=""),"",J9/J25) | M9: =IF(OR(L25=0,L25=""),"",L9/L25)
A10: Discount | C10: =IF(OR(B25=0,B25=""),"",B10/B25) | E10: =IF(OR(D25=0,D25=""),"",D10/D25) | G10: =IF(OR(F25=0,F25=""),"",F10/F25) | I10: =IF(OR(H25=0,H25=""),"",H10/H25) | K10: =IF(OR(J25=0,J25=""),"",J10/J25) | M10: =IF(OR(L25=0,L25=""),"",L10/L25)
A11: Negotiated | C11: =IF(OR(B25=0,B25=""),"",B11/B25) | E11: =IF(OR(D25=0,D25=""),"",D11/D25) | G11: =IF(OR(F25=0,F25=""),"",F11/F25) | I11: =IF(OR(H25=0,H25=""),"",H11/H25) | K11: =IF(OR(J25=0,J25=""),"",J11/J25) | M11: =IF(OR(L25=0,L25=""),"",L11/L25)
A12: Qualified | C12: =IF(OR(B25=0,B25=""),"",B12/B25) | E12: =IF(OR(D25=0,D25=""),"",D12/D25) | G12: =IF(OR(F25=0,F25=""),"",F12/F25) | I12: =IF(OR(H25=0,H25=""),"",H12/H25) | K12: =IF(OR(J25=0,J25=""),"",J12/J25) | M12: =IF(OR(L25=0,L25=""),"",L12/L25)
A13: Wholesale | C13: =IF(OR(B25=0,B25=""),"",B13/B25) | E13: =IF(OR(D25=0,D25=""),"",D13/D25) | G13: =IF(OR(F25=0,F25=""),"",F13/F25) | I13: =IF(OR(H25=0,H25=""),"",H13/H25) | K13: =IF(OR(J25=0,J25=""),"",J13/J25) | M13: =IF(OR(L25=0,L25=""),"",L13/L25)
A14: Total Transient Rooms Revenue | B14: =B9+B10+B11+B12+B13 -> 0 | C14: =IF(OR(B25=0,B25=""),"",B14/B25) | D14: =D9+D10+D11+D12+D13 -> 0 | E14: =IF(OR(D25=0,D25=""),"",D14/D25) | F14: =F9+F10+F11+F12+F13 -> 0 | G14: =IF(OR(F25=0,F25=""),"",F14/F25) | H14: =H9+H10+H11+H12+H13 -> 0 | I14: =IF(OR(H25=0,H25=""),"",H14/H25) | J14: =J9+J10+J11+J12+J13 -> 0 | K14: =IF(OR(J25=0,J25=""),"",J14/J25) | L14: =L9+L10+L11+L12+L13 -> 0 | M14: =IF(OR(L25=0,L25=""),"",L14/L25)
A15: Group Rooms Revenue
A16: Corporate | C16: =IF(OR(B25=0,B25=""),"",B16/B25) | E16: =IF(OR(D25=0,D25=""),"",D16/D25) | G16: =IF(OR(F25=0,F25=""),"",F16/F25) | I16: =IF(OR(H25=0,H25=""),"",H16/H25) | K16: =IF(OR(J25=0,J25=""),"",J16/J25) | M16: =IF(OR(L25=0,L25=""),"",L16/L25)
A17: Association/Convention | C17: =IF(OR(B25=0,B25=""),"",B17/B25) | E17: =IF(OR(D25=0,D25=""),"",D17/D25) | G17: =IF(OR(F25=0,F25=""),"",F17/F25) | I17: =IF(OR(H25=0,H25=""),"",H17/H25) | K17: =IF(OR(J25=0,J25=""),"",J17/J25) | M17: =IF(OR(L25=0,L25=""),"",L17/L25)
A18: Government | C18: =IF(OR(B25=0,B25=""),"",B18/B25) | E18: =IF(OR(D25=0,D25=""),"",D18/D25) | G18: =IF(OR(F25=0,F25=""),"",F18/F25) | I18: =IF(OR(H25=0,H25=""),"",H18/H25) | K18: =IF(OR(J25=0,J25=""),"",J18/J25) | M18: =IF(OR(L25=0,L25=""),"",L18/L25)
A19: Tour/Wholesalers | C19: =IF(OR(B25=0,B25=""),"",B19/B25) | E19: =IF(OR(D25=0,D25=""),"",D19/D25) | G19: =IF(OR(F25=0,F25=""),"",F19/F25) | I19: =IF(OR(H25=0,H25=""),"",H19/H25) | K19: =IF(OR(J25=0,J25=""),"",J19/J25) | M19: =IF(OR(L25=0,L25=""),"",L19/L25)
A20: SMERF | C20: =IF(OR(B25=0,B25=""),"",B20/B25) | E20: =IF(OR(D25=0,D25=""),"",D20/D25) | G20: =IF(OR(F25=0,F25=""),"",F20/F25) | I20: =IF(OR(H25=0,H25=""),"",H20/H25) | K20: =IF(OR(J25=0,J25=""),"",J20/J25) | M20: =IF(OR(L25=0,L25=""),"",L20/L25)
A21: Total Group Rooms Revenue | B21: =B16+B17+B18+B19+B20 -> 0 | C21: =IF(OR(B25=0,B25=""),"",B21/B25) | D21: =D16+D17+D18+D19+D20 -> 0 | E21: =IF(OR(D25=0,D25=""),"",D21/D25) | F21: =F16+F17+F18+F19+F20 -> 0 | G21: =IF(OR(F25=0,F25=""),"",F21/F25) | H21: =H16+H17+H18+H19+H20 -> 0 | I21: =IF(OR(H25=0,H25=""),"",H21/H25) | J21: =J16+J17+J18+J19+J20 -> 0 | K21: =IF(OR(J25=0,J25=""),"",J21/J25) | L21: =L16+L17+L18+L19+L20 -> 0 | M21: =IF(OR(L25=0,L25=""),"",L21/L25)
A22: Contract Rooms Revenue | C22: =IF(OR(B25=0,B25=""),"",B22/B25) | E22: =IF(OR(D25=0,D25=""),"",D22/D25) | G22: =IF(OR(F25=0,F25=""),"",F22/F25) | I22: =IF(OR(H25=0,H25=""),"",H22/H25) | K22: =IF(OR(J25=0,J25=""),"",J22/J25) | M22: =IF(OR(L25=0,L25=""),"",L22/L25)
A23: Other Rooms Revenue | C23: =IF(OR(B25=0,B25=""),"",B23/B25) | E23: =IF(OR(D25=0,D25=""),"",D23/D25) | G23: =IF(OR(F25=0,F25=""),"",F23/F25) | I23: =IF(OR(H25=0,H25=""),"",H23/H25) | K23: =IF(OR(J25=0,J25=""),"",J23/J25) | M23: =IF(OR(L25=0,L25=""),"",L23/L25)
A24: Less: Allowances | C24: =IF(OR(B25=0,B25=""),"",B24/B25) | E24: =IF(OR(D25=0,D25=""),"",D24/D25) | G24: =IF(OR(F25=0,F25=""),"",F24/F25) | I24: =IF(OR(H25=0,H25=""),"",H24/H25) | K24: =IF(OR(J25=0,J25=""),"",J24/J25) | M24: =IF(OR(L25=0,L25=""),"",L24/L25)
A25: Total Rooms Revenue | B25: =B14+B21+B22+B23-B24 -> 0 | C25: =IF(OR(B25=0,B25=""),"",B25/B25) | D25: =D14+D21+D22+D23-D24 -> 0 | E25: =IF(OR(D25=0,D25=""),"",D25/D25) | F25: =F14+F21+F22+F23-F24 -> 0 | G25: =IF(OR(F25=0,F25=""),"",F25/F25) | H25: =H14+H21+H22+H23-H24 -> 0 | I25: =IF(OR(H25=0,H25=""),"",H25/H25) | J25: =J14+J21+J22+J23-J24 -> 0 | K25: =IF(OR(J25=0,J25=""),"",J25/J25) | L25: =L14+L21+L22+L23-L24 -> 0 | M25: =IF(OR(L25=0,L25=""),"",L25/L25)
A26: Expenses
A27: Labor Costs and Related Expenses
A28: Salaries, Wages, Service Charges, Contracted Labor and Bonuses
A29: Salaries and Wages
A30: Management
A31: Non-Management
A32: Front Office
A33: Guest Services
A34: Housekeeping
A35: Laundry
A36: Reservations
A37: Transportation
A38: Sub-Total: Salaries and Wages | B38: =B30+B32+B33+B34+B35+B36+B37 -> 0 | D38: =D30+D32+D33+D34+D35+D36+D37 -> 0 | F38: =F30+F32+F33+F34+F35+F36+F37 -> 0 | H38: =H30+H32+H33+H34+H35+H36+H37 -> 0 | J38: =J30+J32+J33+J34+J35+J36+J37 -> 0 | L38: =L30+L32+L33+L34+L35+L36+L37 -> 0
A39: Service Charge Distribution
A40: Contracted, Leased and Outsourced Labor
...

Sheet Schedule 2 - Food & Beverage
A1: FOOD AND BEVERAGE — SCHEDULE 2
A2: Property: | B2: ='Setup & Assumptions'!$B$4 -> Enter property name | H2: Period / Year: | J2: ='Setup & Assumptions'!$B$5 -> e.g. January 2026 / FY2026
A3: Departmental percentages are calculated on Total Revenue. Departmental Expense (for the Summary) = Cost of Sales + Total Expenses.
B4: Current Period | H4: Year-To-Date
